Workbook

Sheet Character Builder
A1: EDHA CHARACTER BUILDER v2 | N1: TALENT VIEWER | U1: HeroicTalents | V1: Ley1Talents | W1: Ley2Talents | X1: DeityTalents | Y1: AllActiveTalents | Z1: ActiveSpecialties
A2: Cosmere RPG • Edha • Excel 365 • Duplicate this sheet to create additional characters | N2: Look up any talent by name, or browse by path below. | U2: {=IFERROR(_xlfn._xlws.FILTER(Calc!$D$2:$D$375,(Calc!$A$2:$A$375="heroic")*(Calc!$B$2:$B$375=$C$6)*(Calc!$C$2:$C$375<>"Key")),"")} -> Efficient Engineer | V2: {=IFERROR(_xlfn._xlws.FILTER(Calc!$D$2:$D$375,(Calc!$A$2:$A$375="leyline")*(Calc!$B$2:$B$375=$C$7)*(Calc!$C$2:$C$375<>"Key")),"")} -> Primal Awareness | W2: {=IFERROR(_xlfn._xlws.FILTER(Calc!$D$2:$D$375,(Calc!$A$2:$A$375="leyline")*(Calc!$B$2:$B$375=$C$8)*(Calc!$C$2:$C$375<>"Key")),"")} -> Burning Drive | X2: {=IFERROR(_xlfn._xlws.FILTER(Calc!$D$2:$D$375,(Calc!$A$2:$A$375="deity")*(Calc!$B$2:$B$375=$C$9)*(Calc!$C$2:$C$375<>"Key")),"")} -> Pattern Recognition | Y2: {=IFERROR(_xlfn._xlws.FILTER(Calc!$D$2:$D$375,(((Calc!$A$2:$A$375="heroic")*(Calc!$B$2:$B$375=$C$6))+((Calc!$A$2:$A$375="leyline")*(Calc!$B$2:$B$375=$C$7))+((Calc!$A$2:$A$375="leyline")*(Calc!$B$2:$B$375=$C$8))+((Calc!$A$2:$A$375="deity")*(Calc!$B$2:$B$375=$C$9)))*(Calc!$C$2:$C$375<>"Key")),"")} -> Burning Drive | Z2: {=IFERROR(_xlfn.UNIQUE(_xlfn._xlws.FILTER(Calc!$C$2:$C$375,(((Calc!$A$2:$A$375="heroic")*(Calc!$B$2:$B$375=$C$6))+((Calc!$A$2:$A$375="leyline")*(Calc!$B$2:$B$375=$C$7))+((Calc!$A$2:$A$375="leyline")*(Calc!$B$2:$B$375=$C$8))+((Calc!$A$2:$A$375="deity")*(Calc!$B$2:$B$375=$C$9)))*(Calc!$C$2:$C$375<>"Key"))),"")} -> Momentum
U3: Prized Acquisition | V3: Grasping Vines | W3: Reckless Advance | X3: Predator's Taxonomy | Y3: Reckless Advance | Z3: Conflagration
A4: STEP 1: CHARACTER INFO | N4: TALENT DETAIL LOOKUP | U4: Deep Study | V4: Territorial Instinct | W4: Volatile Strike | X4: Environmental Reading | Y4: Volatile Strike | Z4: Frenzy
B5: Name | F5: Level | G5: 11 | J5: Ancestry | K5: Human | N5: Talent Name: | U5: Inventive Design | V5: Thorn Field | W5: Escalating Fury | X5: Reckless Experiment | Y5: Escalating Fury | Z5: Territory
B6: Heroic Path | C6: Scholar | F6: Heroic Specialty | N6: Atlas: | O6: =IFERROR(INDEX(Calc!$A$2:$A$375,MATCH($O$5,Calc!$D$2:$D$375,0)),"") | U6: Fine Handiwork | V6: Verdant Resilience | W6: Shockwave Slam | X6: Trial and Error | Y6: Shockwave Slam | Z6: Restoration
B7: Leyline Path 1 | C7: Green | F7: Leyline Specialty 1 | N7: Path: | O7: =IFERROR(INDEX(Calc!$B$2:$B$375,MATCH($O$5,Calc!$D$2:$D$375,0)),"") | U7: Overcharge | V7: Territorial Claim | W7: Explosive Leap | X7: Passionate Breakthrough | Y7: Explosive Leap | Z7: Instinct
B8: Leyline Path 2 | C8: Red | F8: Leyline Specialty 2 | N8: Specialty: | O8: =IFERROR(INDEX(Calc!$C$2:$C$375,MATCH($O$5,Calc!$D$2:$D$375,0)),"") | U8: Experimental Tinkering | V8: Pack Sense | W8: Reckless Momentum | X8: Shared Revelation | Y8: Reckless Momentum | Z8: Knowledge
B9: Deity Path | C9: Knowledge | F9: Deity Domain | G9: =IF(C9="(None)","",C9) -> Knowledge | N9: Action: | O9: =IFERROR(INDEX(Calc!$E$2:$E$375,MATCH($O$5,Calc!$D$2:$D$375,0)),"") | U9: Overwhelm with Details | V9: Apex Predator | W9: Unstoppable | X9: The Eureka Moment | Y9: Unstoppable | Z9: Artifabrian
N10: Cost: | O10: =IFERROR(INDEX(Calc!$F$2:$F$375,MATCH($O$5,Calc!$D$2:$D$375,0)),"") | U10: Strategize | V10: Mender's Instinct | W10: Kindle | X10: Forbidden Knowledge | Y10: Kindle | Z10: Strategist
A11: PROGRESSION (auto-calculated) | N11: Prerequisites: | O11: =IFERROR(INDEX(Calc!$G$2:$G$375,MATCH($O$5,Calc!$D$2:$D$375,0)),"") | U11: Mind and Body | V11: Verdant Mend | W11: Searing Bolt | X11: #N/A | Y11: Searing Bolt | Z11: Surgeon
B12: Tier | C12: =INT(($G$5-1)/5)+1 -> 3 | D12: Max Skill Rank | E12: =INT(($G$5-1)/5)+2 -> 4 | F12: Attribute Points | G12: =12+SUMPRODUCT(({3,6,9,12,15,18}<=$G$5)*1) -> 15 | H12: Skill Ranks | I12: =5+($G$5-1)*2 -> 25 | J12: Talent Points | K12: =4+$G$5+SUMPRODUCT(({6,11,16}<=$G$5)*1) -> 17 | N12: Description: | O12: =IFERROR(INDEX(Calc!$H$2:$H$375,MATCH($O$5,Calc!$D$2:$D$375,0)),"") | U12: Composed | V12: Root and Branch | W12: Flame Surge | X12: #N/A | Y12: Flame Surge | Z12: #N/A
U13: Know Your Moment | V13: Natural Recovery | W13: Arc Flash | X13: #N/A | Y13: Arc Flash | Z13: #N/A
A14: STEP 2: DISTRIBUTE ATTRIBUTE POINTS | U14: Deep Contemplation | V14: Hardy | W14: Backblast | X14: #N/A | Y14: Backblast | Z14: #N/A
B15: Strength (STR) | D15: Speed (SPD) | F15: Intellect (INT) | H15: Willpower (WIL) | J15: Awareness (AWA) | L15: Presence (PRE) | U15: Keen Insight | V15: Collected | W15: Mighty | X15: #N/A | Y15: Mighty | Z15: #N/A
B16: 2 | D16: 2 | F16: 3 | H16: 1 | J16: 4 | L16: 2 | N16: Prereq Met? | O16: =IFERROR(INDEX(Calc!$I$2:$I$375,MATCH($O$5,Calc!$D$2:$D$375,0)),"") | U16: Contingency | V16: Reknit Form | W16: Afterburn | X16: #N/A | Y16: Afterburn | Z16: #N/A
B17: Points Spent | C17: =B16+D16+F16+H16+J16+L16 -> 14 | E17: Available | F17: =$G$12 -> 15 | H17: Remaining | I17: =F17-C17 -> 1 | U17: Turning Point | V17: Vital Surge | W17: Chain Detonation | X17: #N/A | Y17: Chain Detonation | Z17: #N/A
B18: Level 1 max: 3/attr. Spin buttons deferred to Claude Design. | N18: BROWSE BY PATH | U18: Field Medicine | V18: Predator's Instinct | W18: Incite | X18: #N/A | Y18: Incite | Z18: #N/A
N19: Filter Path: | O19: Scholar | U19: Emotional Intelligence | V19: Pack Hunter | W19: Emotional Overload | X19: #N/A | Y19: Emotional Overload | Z19: #N/A
A20: DERIVED STATS (auto-calculated) | N20: Talent Name | O20: Specialty | P20: Action | Q20: Cost | R20: Description | S20: Prereqs | U20: Anatomical Insight | V20: Scent the Weak | W20: Battle Fever | X20: #N/A | Y20: Battle Fever | Z20: #N/A
B21: Physical Def | D21: Cognitive Def | F21: Spiritual Def | H21: Health | J21: Focus | N21: =IFERROR(INDEX(_xlfn._xlws.FILTER(Calc!$D$2:$D$375,Calc!$B$2:$B$375=$O$19),1),"") -> Erudition | O21: =IFERROR(INDEX(_xlfn._xlws.FILTER(Calc!$C$2:$C$375,Calc!$B$2:$B$375=$O$19),1),"") -> Key | P21: =IFERROR(INDEX(_xlfn._xlws.FILTER(Calc!$E$2:$E$375,Calc!$B$2:$B$375=$O$19),1),"") -> ★ | Q21: =IFERROR(INDEX(_xlfn._xlws.FILTER(Calc!$F$2:$F$375,Calc!$B$2:$B$375=$O$19),1),"") -> 0 | R21: =IFERROR(INDEX(_xlfn._xlws.FILTER(Calc!$H$2:$H$375,Calc!$B$2:$B$375=$O$19),1),"") -> Temporarily gain a cultural or utility expertise and a rank in two non-invested cognitive skills. Reassign these after a long rest with library access. | S21: =IFERROR(INDEX(_xlfn._xlws.FILTER(Calc!$G$2:$G$375,Calc!$B$2:$B$375=$O$19),1),"") -> 0 | U21: Collected | V21: Pack Pressure | W21: Shatter Focus | X21: #N/A | Y21: Shatter Focus | Z21: #N/A
B22: =10+$B$16+$D$16 -> 14 | D22: =10+$F$16+$H$16 -> 14 | F22: =10+$J$16+$L$16 -> 16 | H22: =10+$B$16+($G$5-1)*5+IF($G$5>=6,$B$16-1,0)+IF($G$5>=11,$B$16-2,0)+IF($G$5>=16,$B$16-3,0) -> 63 | J22: =2+$H$16 -> 3 | N22: =IFERROR(INDEX(_xlfn._xlws.FILTER(Calc!$D$2:$D$375,Calc!$B$2:$B$375=$O$19),2),"") -> Efficient Engineer | O22: =IFERROR(INDEX(_xlfn._xlws.FILTER(Calc!$C$2:$C$375,Calc!$B$2:$B$375=$O$19),2),"") -> Artifabrian | P22: =IFERROR(INDEX(_xlfn._xlws.FILTER(Calc!$E$2:$E$375,Calc!$B$2:$B$375=$O$19),2),"") -> ∞ | Q22: =IFERROR(INDEX(_xlfn._xlws.FILTER(Calc!$F$2:$F$375,Calc!$B$2:$B$375=$O$19),2),"") -> 0 | R22: =IFERROR(INDEX(_xlfn._xlws.FILTER(Calc!$H$2:$H$375,Calc!$B$2:$B$375=$O$19),2),"") -> Gain expertise in Armor Crafting, Equipment Crafting, or Weapon Crafting, and gain a fabrial. When crafting, your Opportunity range expands by 2 and your material cost is halved. | S22: =IFERROR(INDEX(_xlfn._xlws.FILTER(Calc!$G$2:$G$375,Calc!$B$2:$B$375=$O$19),2),"") -> Crafting 1+ | U22: Swift Healer | V22: Primal Sight | W22: Reckless Gambit | X22: #N/A | Y22: Reckless Gambit | Z22: #N/A
B23: Investiture | D23: Movement | F23: Recovery Die | H23: Senses Range | J23: Deflect | N23: =IFERROR(INDEX(_xlfn._xlws.FILTER(Calc!$D$2:$D$375,Calc!$B$2:$B$375=$O$19),3),"") -> Prized Acquisition | O23: =IFERROR(INDEX(_xlfn._xlws.FILTER(Calc!$C$2:$C$375,Calc!$B$2:$B$375=$O$19),3),"") -> Artifabrian | P23: =IFERROR(INDEX(_xlfn._xlws.FILTER(Calc!$E$2:$E$375,Calc!$B$2:$B$375=$O$19),3),"") -> ★ | Q23: =IFERROR(INDEX(_xlfn._xlws.FILTER(Calc!$F$2:$F$375,Calc!$B$2:$B$375=$O$19),3),"") -> 0 | R23: =IFERROR(INDEX(_xlfn._xlws.FILTER(Calc!$H$2:$H$375,Calc!$B$2:$B$375=$O$19),3),"") -> Gain Fabrial Crafting expertise. Gain a ê gem you can immediately use to craft a fabrial of your tier. You can reuse this gem for new fabrials. | S23: =IFERROR(INDEX(_xlfn._xlws.FILTER(Calc!$G$2:$G$375,Calc!$B$2:$B$375=$O$19),3),"") -> 0 | U23: Applied Medicine | V23: Surefooted | W23: Contagious Fury | X23: #N/A | Y23: Contagious Fury | Z23: #N/A
B24: =2+MAX($J$16,$L$16) -> 6 | D24: =20+$D$16*5&" ft" -> 30 ft | F24: =INDEX(Reference!$B$51:$B$58,MATCH($H$16,Reference!$A$51:$A$58,1)) -> d4 | H24: =INDEX(Reference!$E$51:$E$57,MATCH($J$16,Reference!$D$51:$D$57,1)) -> 25 ft | J24: =$B$16 -> 2 | N24: =IFERROR(INDEX(_xlfn._xlws.FILTER(Calc!$D$2:$D$375,Calc!$B$2:$B$375=$O$19),4),"") -> Deep Study | O24: =IFERROR(INDEX(_xlfn._xlws.FILTER(Calc!$C$2:$C$375,Calc!$B$2:$B$375=$O$19),4),"") -> Artifabrian | P24: =IFERROR(INDEX(_xlfn._xlws.FILTER(Calc!$E$2:$E$375,Calc!$B$2:$B$375=$O$19),4),"") -> ∞ | Q24: =IFERROR(INDEX(_xlfn._xlws.FILTER(Calc!$F$2:$F$375,Calc!$B$2:$B$375=$O$19),4),"") -> 0 | R24: =IFERROR(INDEX(_xlfn._xlws.FILTER(Calc!$H$2:$H$375,Calc!$B$2:$B$375=$O$19),4),"") -> Erudition grants you an additional cultural or utility expertise and two additional non-invested cognitive skills. | S24: =IFERROR(INDEX(_xlfn._xlws.FILTER(Calc!$G$2:$G$375,Calc!$B$2:$B$375=$O$19),4),"") -> 0 | U24: Ongoing Care | V24: Packmate's Warning | W24: Frenzied Tempo | X24: #N/A | Y24: Frenzied Tempo | Z24: #N/A
N25: =IFERROR(INDEX(_xlfn._xlws.FILTER(Calc!$D$2:$D$375,Calc!$B$2:$B$375=$O$19),5),"") -> Inventive Design | O25: =IFERROR(INDEX(_xlfn._xlws.FILTER(Calc!$C$2:$C$375,Calc!$B$2:$B$375=$O$19),5),"") -> Artifabrian | P25: =IFERROR(INDEX(_xlfn._xlws.FILTER(Calc!$E$2:$E$375,Calc!$B$2:$B$375=$O$19),5),"") -> ∞ | Q25: =IFERROR(INDEX(_xlfn._xlws.FILTER(Calc!$F$2:$F$375,Calc!$B$2:$B$375=$O$19),5),"") -> 0 | R25: =IFERROR(INDEX(_xlfn._xlws.FILTER(Calc!$H$2:$H$375,Calc!$B$2:$B$375=$O$19),5),"") -> Your Prized Acquisition fabrial can have an effect 1 tier higher than the tier you're currently crafting. | S25: =IFERROR(INDEX(_xlfn._xlws.FILTER(Calc!$G$2:$G$375,Calc!$B$2:$B$375=$O$19),5),"") -> Prized Acquisition; Crafting 2+ | U25: Resuscitation | V25: Natural Order | W25: Tyrant's Crescendo | X25: #N/A | Y25: Tyrant's Crescendo | Z25: #N/A
A26: STEP 3: ASSIGN SKILL RANKS | N26: =IFERROR(INDEX(_xlfn._xlws.FILTER(Calc!$D$2:$D$375,Calc!$B$2:$B$375=$O$19),6),"") -> Fine Handiwork | O26: =IFERROR(INDEX(_xlfn._xlws.FILTER(Calc!$C$2:$C$375,Calc!$B$2:$B$375=$O$19),6),"") -> Artifabrian | P26: =IFERROR(INDEX(_xlfn._xlws.FILTER(Calc!$E$2:$E$375,Calc!$B$2:$B$375=$O$19),6),"") -> ★ | Q26: =IFERROR(INDEX(_xlfn._xlws.FILTER(Calc!$F$2:$F$375,Calc!$B$2:$B$375=$O$19),6),"") -> 0 | R26: =IFERROR(INDEX(_xlfn._xlws.FILTER(Calc!$H$2:$H$375,Calc!$B$2:$B$375=$O$19),6),"") -> When crafting, advanced features cost one upgrade instead of two. | S26: =IFERROR(INDEX(_xlfn._xlws.FILTER(Calc!$G$2:$G$375,Calc!$B$2:$B$375=$O$19),6),"") -> Efficient Engineer | U26: #N/A | V26: #N/A | W26: #N/A | X26: #N/A | Y26: Primal Awareness | Z26: #N/A
A27: PHYSICAL | E27: COGNITIVE | I27: SPIRITUAL | N27: =IFERROR(INDEX(_xlfn._xlws.FILTER(Calc!$D$2:$D$375,Calc!$B$2:$B$375=$O$19),7),"") -> Overcharge | O27: =IFERROR(INDEX(_xlfn._xlws.FILTER(Calc!$C$2:$C$375,Calc!$B$2:$B$375=$O$19),7),"") -> Artifabrian | P27: =IFERROR(INDEX(_xlfn._xlws.FILTER(Calc!$E$2:$E$375,Calc!$B$2:$B$375=$O$19),7),"") -> ★ | Q27: =IFERROR(INDEX(_xlfn._xlws.FILTER(Calc!$F$2:$F$375,Calc!$B$2:$B$375=$O$19),7),"") -> 0 | R27: =IFERROR(INDEX(_xlfn._xlws.FILTER(Calc!$H$2:$H$375,Calc!$B$2:$B$375=$O$19),7),"") -> Once per turn, you can raise the stakes on a fabrial attack, then spend Opportunity to Strike with that fabrial as a Free Action. | S27: =IFERROR(INDEX(_xlfn._xlws.FILTER(Calc!$G$2:$G$375,Calc!$B$2:$B$375=$O$19),7),"") -> Prized Acquisition; Crafting 3+ | U27: #N/A | V27: #N/A | W27: #N/A | X27: #N/A | Y27: Grasping Vines | Z27: #N/A
A28: Skill | B28: Rank | C28: Mod | D28: Max | E28: Skill | F28: Rank | G28: Mod | H28: Max | I28: Skill | J28: Rank | K28: Mod | L28: Max | N28: =IFERROR(INDEX(_xlfn._xlws.FILTER(Calc!$D$2:$D$375,Calc!$B$2:$B$375=$O$19),8),"") -> Experimental Tinkering | O28: =IFERROR(INDEX(_xlfn._xlws.FILTER(Calc!$C$2:$C$375,Calc!$B$2:$B$375=$O$19),8),"") -> Artifabrian | P28: =IFERROR(INDEX(_xlfn._xlws.FILTER(Calc!$E$2:$E$375,Calc!$B$2:$B$375=$O$19),8),"") -> ★ | Q28: =IFERROR(INDEX(_xlfn._xlws.FILTER(Calc!$F$2:$F$375,Calc!$B$2:$B$375=$O$19),8),"") -> 0 | R28: =IFERROR(INDEX(_xlfn._xlws.FILTER(Calc!$H$2:$H$375,Calc!$B$2:$B$375=$O$19),8),"") -> When crafting, your Opportunity range expands by 1 and your crafting time is halved. During a long rest, you can reconfigure your Prized Acquisition fabrial to a different fabrial. | S28: =IFERROR(INDEX(_xlfn._xlws.FILTER(Calc!$G$2:$G$375,Calc!$B$2:$B$375=$O$19),8),"") -> Fine Handiwork | U28: #N/A | V28: #N/A | W28: #N/A | X28: #N/A | Y28: Territorial Instinct | Z28: #N/A
A29: Agility (SPD) | B29: 0 | C29: =$D$16+B29 -> 2 | D29: =$E$12 -> 4 | E29: Crafting (INT) | F29: 0 | G29: =$F$16+F29 -> 3 | H29: =$E$12 -> 4 | I29: Deception (PRE) | J29: 0 | K29: =$L$16+J29 -> 2 | L29: =$E$12 -> 4 | N29: =IFERROR(INDEX(_xlfn._xlws.FILTER(Calc!$D$2:$D$375,Calc!$B$2:$B$375=$O$19),9),"") -> Overwhelm with Details | O29: =IFERROR(INDEX(_xlfn._xlws.FILTER(Calc!$C$2:$C$375,Calc!$B$2:$B$375=$O$19),9),"") -> Artifabrian | P29: =IFERROR(INDEX(_xlfn._xlws.FILTER(Calc!$E$2:$E$375,Calc!$B$2:$B$375=$O$19),9),"") -> ★ | Q29: =IFERROR(INDEX(_xlfn._xlws.FILTER(Calc!$F$2:$F$375,Calc!$B$2:$B$375=$O$19),9),"") -> 2 Focus | R29: =IFERROR(INDEX(_xlfn._xlws.FILTER(Calc!$H$2:$H$375,Calc!$B$2:$B$375=$O$19),9),"") -> Spend 2 focus to use your Lore modifier on another cognitive or spiritual test. | S29: =IFERROR(INDEX(_xlfn._xlws.FILTER(Calc!$G$2:$G$375,Calc!$B$2:$B$375=$O$19),9),"") -> Experimental Tinkering; Lore 3+ | U29: #N/A | V29: #N/A | W29: #N/A | X29: #N/A | Y29: Thorn Field | Z29: #N/A
A30: Athletics (STR) | B30: 0 | C30: =$B$16+B30 -> 2 | D30: =$E$12 -> 4 | E30: Deduction (INT) | F30: 3 | G30: =$F$16+F30 -> 6 | H30: =$E$12 -> 4 | I30: Insight (AWA) | J30: 3 | K30: =$J$16+J30 -> 7 | L30: =$E$12 -> 4 | N30: =IFERROR(INDEX(_xlfn._xlws.FILTER(Calc!$D$2:$D$375,Calc!$B$2:$B$375=$O$19),10),"") -> Strategize | O30: =IFERROR(INDEX(_xlfn._xlws.FILTER(Calc!$C$2:$C$375,Calc!$B$2:$B$375=$O$19),10),"") -> Strategist | P30: =IFERROR(INDEX(_xlfn._xlws.FILTER(Calc!$E$2:$E$375,Calc!$B$2:$B$375=$O$19),10),"") -> ★ | Q30: =IFERROR(INDEX(_xlfn._xlws.FILTER(Calc!$F$2:$F$375,Calc!$B$2:$B$375=$O$19),10),"") -> 2 Focus | R30: =IFERROR(INDEX(_xlfn._xlws.FILTER(Calc!$H$2:$H$375,Calc!$B$2:$B$375=$O$19),10),"") -> After you Gain Advantage using an Erudition skill, grant that advantage to an ally instead. You can spend 2 focus to also prevent the target from using reactions against that ally. | S30: =IFERROR(INDEX(_xlfn._xlws.FILTER(Calc!$G$2:$G$375,Calc!$B$2:$B$375=$O$19),10),"") -> Deduction 1+ | U30: #N/A | V30: #N/A | W30: #N/A | X30: #N/A | Y30: Verdant Resilience | Z30: #N/A
A31: Heavy Weaponry (STR) | B31: 0 | C31: =$B$16+B31 -> 2 | D31: =$E$12 -> 4 | E31: Discipline (WIL) | F31: 0 | G31: =$H$16+F31 -> 1 | H31: =$E$12 -> 4 | I31: Leadership (PRE) | J31: 0 | K31: =$L$16+J31 -> 2 | L31: =$E$12 -> 4 | N31: =IFERROR(INDEX(_xlfn._xlws.FILTER(Calc!$D$2:$D$375,Calc!$B$2:$B$375=$O$19),11),"") -> Mind and Body | O31: =IFERROR(INDEX(_xlfn._xlws.FILTER(Calc!$C$2:$C$375,Calc!$B$2:$B$375=$O$19),11),"") -> Strategist | P31: =IFERROR(INDEX(_xlfn._xlws.FILTER(Calc!$E$2:$E$375,Calc!$B$2:$B$375=$O$19),11),"") -> ∞ | Q31: =IFERROR(INDEX(_xlfn._xlws.FILTER(Calc!$F$2:$F$375,Calc!$B$2:$B$375=$O$19),11),"") -> 0 | R31: =IFERROR(INDEX(_xlfn._xlws.FILTER(Calc!$H$2:$H$375,Calc!$B$2:$B$375=$O$19),11),"") -> Gain a weapon expertise. Gain an additional skill from Erudition. You can now choose physical skills with Erudition. | S31: =IFERROR(INDEX(_xlfn._xlws.FILTER(Calc!$G$2:$G$375,Calc!$B$2:$B$375=$O$19),11),"") -> 0 | U31: #N/A | V31: #N/A | W31: #N/A | X31: #N/A | Y31: Territorial Claim
A32: Light Weaponry (SPD) | B32: 2 | C32: =$D$16+B32 -> 4 | D32: =$E$12 -> 4 | E32: Intimidation (WIL) | F32: 0 | G32: =$H$16+F32 -> 1 | H32: =$E$12 -> 4 | I32: Perception (AWA) | J32: 0 | K32: =$J$16+J32 -> 4 | L32: =$E$12 -> 4 | N32: =IFERROR(INDEX(_xlfn._xlws.FILTER(Calc!$D$2:$D$375,Calc!$B$2:$B$375=$O$19),12),"") -> Composed | O32: =IFERROR(INDEX(_xlfn._xlws.FILTER(Calc!$C$2:$C$375,Calc!$B$2:$B$375=$O$19),12),"") -> Strategist | P32: =IFERROR(INDEX(_xlfn._xlws.FILTER(Calc!$E$2:$E$375,Calc!$B$2:$B$375=$O$19),12),"") -> ∞ | Q32: =IFERROR(INDEX(_xlfn._xlws.FILTER(Calc!$F$2:$F$375,Calc!$B$2:$B$375=$O$19),12),"") -> 0 | R32: =IFERROR(INDEX(_xlfn._xlws.FILTER(Calc!$H$2:$H$375,Calc!$B$2:$B$375=$O$19),12),"") -> Increase your max and current focus by your tier. | S32: =IFERROR(INDEX(_xlfn._xlws.FILTER(Calc!$G$2:$G$375,Calc!$B$2:$B$375=$O$19),12),"") -> Strategize | U32: #N/A | V32: #N/A | W32: #N/A | X32: #N/A | Y32: Pack Sense
A33: Stealth (SPD) | B33: 0 | C33: =$D$16+B33 -> 2 | D33: =$E$12 -> 4 | E33: Lore (INT) | F33: 3 | G33: =$F$16+F33 -> 6 | H33: =$E$12 -> 4 | I33: Persuasion (PRE) | J33: 0 | K33: =$L$16+J33 -> 2 | L33: =$E$12 -> 4 | N33: =IFERROR(INDEX(_xlfn._xlws.FILTER(Calc!$D$2:$D$375,Calc!$B$2:$B$375=$O$19),13),"") -> Know Your Moment | O33: =IFERROR(INDEX(_xlfn._xlws.FILTER(Calc!$C$2:$C$375,Calc!$B$2:$B$375=$O$19),13),"") -> Strategist | P33: =IFERROR(INDEX(_xlfn._xlws.FILTER(Calc!$E$2:$E$375,Calc!$B$2:$B$375=$O$19),13),"") -> ∞ | Q33: =IFERROR(INDEX(_xlfn._xlws.FILTER(Calc!$F$2:$F$375,Calc!$B$2:$B$375=$O$19),13),"") -> 0 | R33: =IFERROR(INDEX(_xlfn._xlws.FILTER(Calc!$H$2:$H$375,Calc!$B$2:$B$375=$O$19),13),"") -> Your defenses increase by 2 from the start of each round until you take your turn. | S33: =IFERROR(INDEX(_xlfn._xlws.FILTER(Calc!$G$2:$G$375,Calc!$B$2:$B$375=$O$19),13),"") -> Mind and Body; Deduction 2+ | U33: #N/A | V33: #N/A | W33: #N/A | X33: #N/A | Y33: Apex Predator
A34: Thievery (SPD) | B34: 0 | C34: =$D$16+B34 -> 2 | D34: =$E$12 -> 4 | E34: Medicine (INT) | F34: 0 | G34: =$F$16+F34 -> 3 | H34: =$E$12 -> 4 | I34: Survival (AWA) | J34: 1 | K34: =$J$16+J34 -> 5 | L34: =$E$12 -> 4 | N34: =IFERROR(INDEX(_xlfn._xlws.FILTER(Calc!$D$2:$D$375,Calc!$B$2:$B$375=$O$19),14),"") -> Deep Contemplation | O34: =IFERROR(INDEX(_xlfn._xlws.FILTER(Calc!$C$2:$C$375,Calc!$B$2:$B$375=$O$19),14),"") -> Strategist | P34: =IFERROR(INDEX(_xlfn._xlws.FILTER(Calc!$E$2:$E$375,Calc!$B$2:$B$375=$O$19),14),"") -> ▶▶ | Q34: =IFERROR(INDEX(_xlfn._xlws.FILTER(Calc!$F$2:$F$375,Calc!$B$2:$B$375=$O$19),14),"") -> 0 | R34: =IFERROR(INDEX(_xlfn._xlws.FILTER(Calc!$H$2:$H$375,Calc!$B$2:$B$375=$O$19),14),"") -> Reassign up to 2 skills and expertises from Erudition | S34: =IFERROR(INDEX(_xlfn._xlws.FILTER(Calc!$G$2:$G$375,Calc!$B$2:$B$375=$O$19),14),"") -> Composed; Lore 2+ | U34: #N/A | V34: #N/A | W34: #N/A | X34: #N/A | Y34: Mender's Instinct
A35: =IF(OR($C$7="",$C$7="(None)"),"—",$C$7&" ("&IFERROR(INDEX({"STR","SPD","INT","WIL","AWA","PRE"},VLOOKUP($C$7,Reference!$E$29:$F$43,2,FALSE)),"")&")") -> Green (AWA) | B35: 2 | C35: =IFERROR(INDEX($B$16:$L$16,1,VLOOKUP($C$7,Reference!$E$29:$F$43,2,FALSE)*2-1)+B35,"") -> 6 | D35: =$E$12 -> 4 | E35: =IF(OR($C$8="",$C$8="(None)"),"—",$C$8&" ("&IFERROR(INDEX({"STR","SPD","INT","WIL","AWA","PRE"},VLOOKUP($C$8,Reference!$E$29:$F$43,2,FALSE)),"")&")") -> Red (STR) | F35: 2 | G35: =IFERROR(INDEX($B$16:$L$16,1,VLOOKUP($C$8,Reference!$E$29:$F$43,2,FALSE)*2-1)+F35,"") -> 4 | H35: =$E$12 -> 4 | I35: =IF(OR($C$9="",$C$9="(None)"),"—",$C$9&" ("&IFERROR(INDEX({"STR","SPD","INT","WIL","AWA","PRE"},VLOOKUP($C$9,Reference!$E$29:$F$43,2,FALSE)),"")&")") -> Knowledge (AWA) | J35: 1 | K35: =IFERROR(INDEX($B$16:$L$16,1,VLOOKUP($C$9,Reference!$E$29:$F$43,2,FALSE)*2-1)+J35,"") -> 5 | L35: =$E$12 -> 4 | N35: =IFERROR(INDEX(_xlfn._xlws.FILTER(Calc!$D$2:$D$375,Calc!$B$2:$B$375=$O$19),15),"") -> Keen Insight | O35: =IFERROR(INDEX(_xlfn._xlws.FILTER(Calc!$C$2:$C$375,Calc!$B$2:$B$375=$O$19),15),"") -> Strategist | P35: =IFERROR(INDEX(_xlfn._xlws.FILTER(Calc!$E$2:$E$375,Calc!$B$2:$B$375=$O$19),15),"") -> ∞ | Q35: =IFERROR(INDEX(_xlfn._xlws.FILTER(Calc!$F$2:$F$375,Calc!$B$2:$B$375=$O$19),15),"") -> 0 | R35: =IFERROR(INDEX(_xlfn._xlws.FILTER(Calc!$H$2:$H$375,Calc!$B$2:$B$375=$O$19),15),"") -> After you Gain Advantage, the target must resist your influence or gain a disadvantage on their next test. | S35: =IFERROR(INDEX(_xlfn._xlws.FILTER(Calc!$G$2:$G$375,Calc!$B$2:$B$375=$O$19),15),"") -> Deep Contemplation | U35: #N/A | V35: #N/A | W35: #N/A | X35: #N/A | Y35: Verdant Mend
N36: =IFERROR(INDEX(_xlfn._xlws.FILTER(Calc!$D$2:$D$375,Calc!$B$2:$B$375=$O$19),16),"") -> Contingency | O36: =IFERROR(INDEX(_xlfn._xlws.FILTER(Calc!$C$2:$C$375,Calc!$B$2:$B$375=$O$19),16),"") -> Strategist | P36: =IFERROR(INDEX(_xlfn._xlws.FILTER(Calc!$E$2:$E$375,Calc!$B$2:$B$375=$O$19),16),"") -> ⟲ | Q36: =IFERROR(INDEX(_xlfn._xlws.FILTER(Calc!$F$2:$F$375,Calc!$B$2:$B$375=$O$19),16),"") -> 2 Focus | R36: =IFERROR(INDEX(_xlfn._xlws.FILTER(Calc!$H$2:$H$375,Calc!$B$2:$B$375=$O$19),16),"") -> Spend 2 focus to remove Complication from the test of an ally within 20 ft. | S36: =IFERROR(INDEX(_xlfn._xlws.FILTER(Calc!$G$2:$G$375,Calc!$B$2:$B$375=$O$19),16),"") -> Composed; Lore 3+ | U36: #N/A | V36: #N/A | W36: #N/A | X36: #N/A | Y36: Root and Branch
A37: Ranks Spent | B37: =B29+B30+B31+B32+B33+B34+F29+F30+F31+F32+F33+F34+J29+J30+J31+J32+J33+J34+B35+F35+J35 -> 17 | D37: Available | E37: =$I$12 -> 25 | G37: Remaining | H37: =E37-B37 -> 8 | N37: =IFERROR(INDEX(_xlfn._xlws.FILTER(Calc!$D$2:$D$375,Calc!$B$2:$B$375=$O$19),17),"") -> Turning Point | O37: =IFERROR(INDEX(_xlfn._xlws.FILTER(Calc!$C$2:$C$375,Calc!$B$2:$B$375=$O$19),17),"") -> Strategist | P37: =IFERROR(INDEX(_xlfn._xlws.FILTER(Calc!$E$2:$E$375,Calc!$B$2:$B$375=$O$19),17),"") -> ▶▶ | Q37: =IFERROR(INDEX(_xlfn._xlws.FILTER(Calc!$F$2:$F$375,Calc!$B$2:$B$375=$O$19),17),"") -> 2 Focus | R37: =IFERROR(INDEX(_xlfn._xlws.FILTER(Calc!$H$2:$H$375,Calc!$B$2:$B$375=$O$19),17),"") -> Spend 2 focus to test Deduction vs. Cognitive of the enemy leader, gaining an advantage if you took a slow turn. On a success, you and your allies gain an Action on your next turns. | S37: =IFERROR(INDEX(_xlfn._xlws.FILTER(Calc!$G$2:$G$375,Calc!$B$2:$B$375=$O$19),17),"") -> Contingency; Deduction 3+ | U37: #N/A | V37: #N/A | W37: #N/A | X37: #N/A | Y37: Natural Recovery
N38: =IFERROR(INDEX(_xlfn._xlws.FILTER(Calc!$D$2:$D$375,Calc!$B$2:$B$375=$O$19),18),"") -> Field Medicine | O38: =IFERROR(INDEX(_xlfn._xlws.FILTER(Calc!$C$2:$C$375,Calc!$B$2:$B$375=$O$19),18),"") -> Surgeon | P38: =IFERROR(INDEX(_xlfn._xlws.FILTER(Calc!$E$2:$E$375,Calc!$B$2:$B$375=$O$19),18),"") -> ▶ | Q38: =IFERROR(INDEX(_xlfn._xlws.FILTER(Calc!$F$2:$F$375,Calc!$B$2:$B$375=$O$19),18),"") -> 1 Focus | R38: =IFERROR(INDEX(_xlfn._xlws.FILTER(Calc!$H$2:$H$375,Calc!$B$2:$B$375=$O$19),18),"") -> Spend 1 focus and test Medicine (DC 15) to heal a concious character. On success, add your ranks in Medicine to their recovery die. | S38: =IFERROR(INDEX(_xlfn._xlws.FILTER(Calc!$G$2:$G$375,Calc!$B$2:$B$375=$O$19),18),"") -> Medicine 1+ | U38: #N/A | V38: #N/A | W38: #N/A | X38: #N/A | Y38: Hardy
A39: STEP 4: SELECT TALENTS | N39: =IFERROR(INDEX(_xlfn._xlws.FILTER(Calc!$D$2:$D$375,Calc!$B$2:$B$375=$O$19),19),"") -> Emotional Intelligence | O39: =IFERROR(INDEX(_xlfn._xlws.FILTER(Calc!$C$2:$C$375,Calc!$B$2:$B$375=$O$19),19),"") -> Surgeon | P39: =IFERROR(INDEX(_xlfn._xlws.FILTER(Calc!$E$2:$E$375,Calc!$B$2:$B$375=$O$19),19),"") -> ∞ | Q39: =IFERROR(INDEX(_xlfn._xlws.FILTER(Calc!$F$2:$F$375,Calc!$B$2:$B$375=$O$19),19),"") -> 0 | R39: =IFERROR(INDEX(_xlfn._xlws.FILTER(Calc!$H$2:$H$375,Calc!$B$2:$B$375=$O$19),19),"") -> Gain Diagnosis expertise. Gain an additional skill from Erudtition. You can now choose Spiritual skills with Erudition. | S39: =IFERROR(INDEX(_xlfn._xlws.FILTER(Calc!$G$2:$G$375,Calc!$B$2:$B$375=$O$19),19),"") -> 0 | U39: #N/A | V39: #N/A | W39: #N/A | X39: #N/A | Y39: Collected
B40: Total Talent Points | D40: =$K$12 -> 17 | N40: =IFERROR(INDEX(_xlfn._xlws.FILTER(Calc!$D$2:$D$375,Calc!$B$2:$B$375=$O$19),20),"") -> Anatomical Insight | O40: =IFERROR(INDEX(_xlfn._xlws.FILTER(Calc!$C$2:$C$375,Calc!$B$2:$B$375=$O$19),20),"") -> Surgeon | P40: =IFERROR(INDEX(_xlfn._xlws.FILTER(Calc!$E$2:$E$375,Calc!$B$2:$B$375=$O$19),20),"") -> ★ | Q40: =IFERROR(INDEX(_xlfn._xlws.FILTER(Calc!$F$2:$F$375,Calc!$B$2:$B$375=$O$19),20),"") -> 1 Focus or Opportunity | R40: =IFERROR(INDEX(_xlfn._xlws.FILTER(Calc!$H$2:$H$375,Calc!$B$2:$B$375=$O$19),20),"") -> When you hit with an unarmed attack, spend 1 focus or Opportunity to make the target Exhausted [ - half your ranks in Medicine]. | S40: =IFERROR(INDEX(_xlfn._xlws.FILTER(Calc!$G$2:$G$375,Calc!$B$2:$B$375=$O$19),20),"") -> Field Medicine | U40: #N/A | V40: #N/A | W40: #N/A | X40: #N/A | Y40: Reknit Form
...

Sheet Reference
A1: EDHA REFERENCE TABLES
A3: LEVEL PROGRESSION
A4: Level | B4: Tier | C4: Max Skill | D4: Attr Pts | E4: Skill Ranks | F4: Talent Pts | G4: HP Gain | H4: Cumul HP (S=0)
A5: 1 | B5: 1 | C5: 2 | D5: 12 | E5: 5 | F5: 5 | G5: 10+STR | H5: 10
A6: 2 | B6: 1 | C6: 2 | D6: 12 | E6: 7 | F6: 6 | G6: +5 | H6: 15
A7: 3 | B7: 1 | C7: 2 | D7: 13 | E7: 9 | F7: 7 | G7: +5 | H7: 20
A8: 4 | B8: 1 | C8: 2 | D8: 13 | E8: 11 | F8: 8 | G8: +5 | H8: 25
A9: 5 | B9: 1 | C9: 2 | D9: 13 | E9: 13 | F9: 9 | G9: +5 | H9: 30
A10: 6 | B10: 2 | C10: 3 | D10: 14 | E10: 15 | F10: 11 | G10: 4+STR | H10: 34
A11: 7 | B11: 2 | C11: 3 | D11: 14 | E11: 17 | F11: 12 | G11: +5 | H11: 39
A12: 8 | B12: 2 | C12: 3 | D12: 14 | E12: 19 | F12: 13 | G12: +5 | H12: 44
A13: 9 | B13: 2 | C13: 3 | D13: 15 | E13: 21 | F13: 14 | G13: +5 | H13: 49
A14: 10 | B14: 2 | C14: 3 | D14: 15 | E14: 23 | F14: 15 | G14: +5 | H14: 54
A15: 11 | B15: 3 | C15: 4 | D15: 15 | E15: 25 | F15: 17 | G15: 3+STR | H15: 57
A16: 12 | B16: 3 | C16: 4 | D16: 16 | E16: 27 | F16: 18 | G16: +5 | H16: 62
... A24: 20 | B24: 4 | C24: 5 | D24: 18 | E24: 43 | F24: 27 | G24: +5 | H24: 99
A27: SKILLS & ATTRIBUTES | E27: PATH → ATTR#
A28: Skill | B28: Attr | C28: # | E28: Path | F28: Idx
A29: Agility | B29: SPD | C29: 1 | E29: Black | F29: 6
A30: Athletics | B30: STR | C30: 2 | E30: Blue | F30: 3
A31: Heavy Weaponry | B31: STR | C31: 3 | E31: Chaos | F31: 6
A32: Light Weaponry | B32: SPD | C32: 4 | E32: Civilization | F32: 4
A33: Stealth | B33: SPD | C33: 5 | E33: Death | F33: 6
A34: Thievery | B34: SPD | C34: 6 | E34: Destruction | F34: 1
A35: Crafting | B35: INT | C35: 7 | E35: Fate | F35: 4
A36: Deduction | B36: INT | C36: 8 | E36: Green | F36: 5
A37: Discipline | B37: WIL | C37: 9 | E37: Knowledge | F37: 5
A38: Intimidation | B38: WIL | C38: 10 | E38: Life | F38: 5
A39: Lore | B39: INT | C39: 11 | E39: Order | F39: 4
A40: Medicine | B40: INT | C40: 12 | E40: Power | F40: 1
... A43: Leadership | B43: PRE | C43: 15 | E43: White | F43: 4
A44: Perception | B44: AWA | C44: 16
A45: Persuasion | B45: PRE | C45: 17
A46: Survival | B46: AWA | C46: 18
A50: RECOVERY DIE | D50: SENSES RANGE
A51: 0 | B51: d4 | D51: 0 | E51: 10 ft
A52: 1 | B52: d4 | D52: 1 | E52: 15 ft
A53: 2 | B53: d6 | D53: 2 | E53: 20 ft
A54: 3 | B54: d6 | D54: 3 | E54: 20 ft
A55: 4 | B55: d8 | D55: 4 | E55: 25 ft
...

Sheet Calc
A1: Atlas | B1: Path | C1: Specialty | D1: Name | E1: Action | F1: Cost | G1: Prerequisites | H1: Description | I1: PrereqOK | K1: SkillName | L1: Rank | N1: SelectedTalents
A2: leyline | B2: White | C2: Key | D2: White Leyline Attunement | E2: ∞ | H2: When you Draw Mana, allies within Attunement Range regain HP equal to your Tier. | I2: =TRUE -> TRUE | K2: Agility | L2: ='Character Builder'!B29 -> 0 | N2: ='Character Builder'!$C$42 -> Scent the Weak
A3: leyline | B3: White | C3: Coordination | D3: Concordant Presence | E3: ★ | H3: When an ally within Attunement Range succeeds on a test, the next ally testing that same skill this round rolls the Plot Die. | I3: =TRUE -> TRUE | K3: Athletics | L3: ='Character Builder'!B30 -> 0 | N3: ='Character Builder'!$C$44 -> Erudition
A4: leyline | B4: White | C4: Coordination | D4: Ordered Preparation | E4: ★ | G4: Concordant Presence | H4: When you aid an ally's test, add half [Die] to the result instead of the normal aid bonus. | I4: =COUNTIF($N$2:$N$50,"Concordant Presence")>0 -> FALSE | K4: Heavy Weaponry | L4: ='Character Builder'!B31 -> 0 | N4: ='Character Builder'!$C$46 -> Strategize
A5: leyline | B5: White | C5: Coordination | D5: Unity of Purpose | E5: ∞ | G5: Concordant Presence | H5: When two or more allies aid the same test, increase the aid bonus by 1 and roll the Plot Die. | I5: =COUNTIF($N$2:$N$50,"Concordant Presence")>0 -> FALSE | K5: Light Weaponry | L5: ='Character Builder'!B32 -> 2 | N5: ='Character Builder'!$C$48 -> Green Leyline Attunement
A6: leyline | B6: White | C6: Coordination | D6: Beacon of Stability | E6: ★ | F6: Opportunity | G6: White 2+; Ordered Preparation or Unity of Purpose | H6: When you Draw Mana, spend Opportunity to remove one condition from an ally within Attunement Range. | I6: =AND(IFERROR(INDEX($L$2:$L$22,MATCH("White",$K$2:$K$22,0)),0)>=2,OR(COUNTIF($N$2:$N$50,"Ordered Preparation")>0,COUNTIF($N$2:$N$50,"Unity of Purpose")>0)) -> FALSE | K6: Stealth | L6: ='Character Builder'!B33 -> 0 | N6: ='Character Builder'!$C$50 -> Predator's Instinct
A7: leyline | B7: White | C7: Coordination | D7: Shared Conviction | E7: ⟲ | F7: 1 Focus | G7: Beacon of Stability | H7: When an ally within Attunement Range fails a test, add half [Die] to their result. This may change the outcome. | I7: =COUNTIF($N$2:$N$50,"Beacon of Stability")>0 -> FALSE | K7: Thievery | L7: ='Character Builder'!B34 -> 0 | N7: ='Character Builder'!$C$54 -> Incite
A8: leyline | B8: White | C8: Coordination | D8: Ordered Advance | E8: ★ | G8: Beacon of Stability | H8: When you Move, up to Tier allies within 10 ft may move half their Speed without provoking Reactions. | I8: =COUNTIF($N$2:$N$50,"Beacon of Stability")>0 -> FALSE | K8: Crafting | L8: ='Character Builder'!F29 -> 0 | N8: ='Character Builder'!$C$55 -> Burning Drive
A9: leyline | B9: White | C9: Coordination | D9: Mending Aura | E9: ★ | F9: Opportunity | G9: White 2+; Ordered Advance or Shared Conviction | H9: When you Draw Mana, spend Opportunity to restore half [Die] HP to each ally within [Size]. | I9: =AND(IFERROR(INDEX($L$2:$L$22,MATCH("White",$K$2:$K$22,0)),0)>=2,OR(COUNTIF($N$2:$N$50,"Ordered Advance")>0,COUNTIF($N$2:$N$50,"Shared Conviction")>0)) -> FALSE | K9: Deduction | L9: ='Character Builder'!F30 -> 3 | N9: ='Character Builder'!$C$56 -> Mind and Body
A10: leyline | B10: White | C10: Coordination | D10: Pillar of Order | E10: ⟲ | G10: Mending Aura; White 3+ | H10: When an ally within Attunement Range rolls a Complication, change it to a blank face. Once per round. | I10: =AND(COUNTIF($N$2:$N$50,"Mending Aura")>0,IFERROR(INDEX($L$2:$L$22,MATCH("White",$K$2:$K$22,0)),0)>=3) -> FALSE | K10: Discipline | L10: ='Character Builder'!F31 -> 0 | N10: ='Character Builder'!$C$57 -> Know Your Moment
A11: leyline | B11: White | C11: Bulwark | D11: Guardian Stance | E11: ∞ | H11: While an ally is adjacent to you, you both gain +1 Deflect. | I11: =TRUE -> TRUE | K11: Intimidation | L11: ='Character Builder'!F32 -> 0 | N11: ='Character Builder'!$C$58 -> 0
A12: leyline | B12: White | C12: Bulwark | D12: Interposing Shield | E12: ⟲ | F12: 1 Investiture | G12: Guardian Stance | H12: When an ally within 10 ft takes damage, move up to 10 ft toward them and reduce that damage by half [Die]. | I12: =COUNTIF($N$2:$N$50,"Guardian Stance")>0 -> FALSE | K12: Lore | L12: ='Character Builder'!F33 -> 3 | N12: ='Character Builder'!$C$59 -> 0
A13: leyline | B13: White | C13: Bulwark | D13: Stabilizing Touch | E13: ▶ | F13: 1 Investiture | G13: Guardian Stance | H13: Touch a creature to restore [Die] HP. If below half HP, restore [Die] + half [Die] instead. | I13: =COUNTIF($N$2:$N$50,"Guardian Stance")>0 -> FALSE | K13: Medicine | L13: ='Character Builder'!F34 -> 0 | N13: ='Character Builder'!$C$60 -> 0
A14: leyline | B14: White | C14: Bulwark | D14: Shared Burden | E14: ★ | G14: Interposing Shield or Stabilizing Touch | H14: When an ally adjacent to you takes damage, you may take half that damage in their place. Once per round. | I14: =OR(COUNTIF($N$2:$N$50,"Interposing Shield")>0,COUNTIF($N$2:$N$50,"Stabilizing Touch")>0) -> FALSE | K14: Deception | L14: ='Character Builder'!J29 -> 0 | N14: ='Character Builder'!$C$61 -> 0
A15: leyline | B15: White | C15: Bulwark | D15: Devoted Conduit | E15: ∞ | G15: Shared Burden | H15: When an ally within Attunement Range takes damage intended for another creature, reduce that damage by half [Die]. | I15: =COUNTIF($N$2:$N$50,"Shared Burden")>0 -> FALSE | K15: Insight | L15: ='Character Builder'!J30 -> 3 | N15: ='Character Builder'!$C$62 -> 0
A16: leyline | B16: White | C16: Bulwark | D16: Shield Wall | E16: ∞ | G16: Shared Burden | H16: When two or more allies are adjacent to each other, attacks against them deal half [Die] less damage. | I16: =COUNTIF($N$2:$N$50,"Shared Burden")>0 -> FALSE | K16: Leadership | L16: ='Character Builder'!J31 -> 0 | N16: ='Character Builder'!$C$63 -> 0
A17: leyline | B17: White | C17: Bulwark | D17: Unbreakable Line | E17: ∞ | G17: White 2+; Shield Wall or Devoted Conduit | H17: Once per round, when an ally adjacent to you would drop to 0 HP, they drop to 1 HP instead. | I17: =AND(IFERROR(INDEX($L$2:$L$22,MATCH("White",$K$2:$K$22,0)),0)>=2,OR(COUNTIF($N$2:$N$50,"Shield Wall")>0,COUNTIF($N$2:$N$50,"Devoted Conduit")>0)) -> FALSE | K17: Perception | L17: ='Character Builder'!J32 -> 0 | N17: ='Character Builder'!$C$64 -> 0
A18: leyline | B18: White | C18: Bulwark | D18: Hardy | E18: ∞ | G18: Unbreakable Line; White 3+ | H18: Gain +1 maximum HP per level, including previous levels. | I18: =AND(COUNTIF($N$2:$N$50,"Unbreakable Line")>0,IFERROR(INDEX($L$2:$L$22,MATCH("White",$K$2:$K$22,0)),0)>=3) -> FALSE | K18: Persuasion | L18: ='Character Builder'!J33 -> 0 | N18: ='Character Builder'!$C$65 -> 0
A19: leyline | B19: White | C19: Accord | D19: Terms of Accord | E19: ∞ | H19: When you and a willing creature verbally agree on a shared objective, both gain +1 to tests pursuing it for the scene. One active accord per creature. | I19: =TRUE -> TRUE | K19: Survival | L19: ='Character Builder'!J34 -> 1 | N19: ='Character Builder'!$C$66 -> 0
A20: leyline | B20: White | C20: Accord | D20: Calming Presence | E20: ∞ | G20: Terms of Accord | H20: Allies within your Attunement Range gain +1 to defenses against Influence and fear effects. | I20: =COUNTIF($N$2:$N$50,"Terms of Accord")>0 -> FALSE | K20: =IF(OR($C$7="",$C$7="(None)"),"",$C$7) -> Coordination | L20: ='Character Builder'!B35 -> 2 | N20: ='Character Builder'!$C$67 -> 0
A21: leyline | B21: White | C21: Accord | D21: Disciplined Mind | E21: ∞ | G21: Terms of Accord | H21: You and allies within Attunement Range reduce the Focus cost to resist Influence by 1 (minimum 1). | I21: =COUNTIF($N$2:$N$50,"Terms of Accord")>0 -> FALSE | K21: =IF(OR($C$8="",$C$8="(None)"),"",$C$8) -> Coordination | L21: ='Character Builder'!F35 -> 2 | N21: ='Character Builder'!$C$68 -> 0
A22: leyline | B22: White | C22: Accord | D22: Commanding Presence | E22: ★ | G22: White 2+; Calming Presence or Disciplined Mind | H22: When you succeed on an Influence test, the target also becomes Disoriented until the end of your next turn. | I22: =AND(IFERROR(INDEX($L$2:$L$22,MATCH("White",$K$2:$K$22,0)),0)>=2,OR(COUNTIF($N$2:$N$50,"Calming Presence")>0,COUNTIF($N$2:$N$50,"Disciplined Mind")>0)) -> FALSE | K22: =IF(OR($C$9="",$C$9="(None)"),"",$C$9) -> Coordination | L22: ='Character Builder'!J35 -> 1 | N22: ='Character Builder'!$C$69 -> 0
A23: leyline | B23: White | C23: Accord | D23: Shared Discipline | E23: ∞ | G23: Commanding Presence | H23: Allies within Attunement Range ignore the first instance of Disoriented each round. | I23: =COUNTIF($N$2:$N$50,"Commanding Presence")>0 -> FALSE | N23: ='Character Builder'!$C$70 -> 0
A24: leyline | B24: White | C24: Accord | D24: Collective Resolve | E24: ★ | F24: Opportunity | G24: Shared Discipline | H24: When an ally within Attunement Range succeeds on a test, spend Opportunity to grant them Determined. | I24: =COUNTIF($N$2:$N$50,"Shared Discipline")>0 -> FALSE | N24: ='Character Builder'!$C$71 -> 0
A25: leyline | B25: White | C25: Accord | D25: Unyielding Accord | E25: ∞ | G25: Shared Discipline | H25: Allies within Attunement Range gain +1 to Cognitive and Spiritual defenses while adjacent to another ally. | I25: =COUNTIF($N$2:$N$50,"Shared Discipline")>0 -> FALSE | N25: ='Character Builder'!$C$72 -> 0
A26: leyline | B26: White | C26: Accord | D26: Voice of Authority | E26: ⟲ | G26: White 3+; Collective Resolve or Unyielding Accord | H26: When an enemy within Attunement Range targets an ally with a hostile action, impose Disadvantage. Once per round. | I26: =AND(IFERROR(INDEX($L$2:$L$22,MATCH("White",$K$2:$K$22,0)),0)>=3,OR(COUNTIF($N$2:$N$50,"Collective Resolve")>0,COUNTIF($N$2:$N$50,"Unyielding Accord")>0)) -> FALSE | N26: ='Character Builder'!$C$73 -> 0
A27: leyline | B27: Blue | C27: Key | D27: Blue Leyline Attunement | E27: ∞ | H27: When you Draw Mana, gain Advantage on your next Cognitive test. | I27: =TRUE -> TRUE | N27: ='Character Builder'!$C$74 -> 0
A28: leyline | B28: Blue | C28: Foresight | D28: Predictive Awareness | E28: ∞ | H28: At the start of each scene, choose one skill. Your first test using that skill gains Advantage. | I28: =TRUE -> TRUE | N28: ='Character Builder'!$C$75 -> 0
A29: leyline | B29: Blue | C29: Foresight | D29: Future Vector | E29: ★ | G29: Predictive Awareness | H29: When you test against a creature or objective for the first time this scene, also roll the Plot Die. | I29: =COUNTIF($N$2:$N$50,"Predictive Awareness")>0 -> FALSE | N29: ='Character Builder'!$H$54 -> 0
A30: leyline | B30: Blue | C30: Foresight | D30: Telepathic Network | E30: ▶▶ | F30: 2 Investiture | G30: Predictive Awareness | H30: You communicate telepathically with willing creatures within Attunement Range until the end of the scene. Allies in the network share your Expertise. | I30: =COUNTIF($N$2:$N$50,"Predictive Awareness")>0 -> FALSE | N30: ='Character Builder'!$H$55 -> 0
A31: leyline | B31: Blue | C31: Foresight | D31: Calculated Patience | E31: ∞ | G31: Blue 2+; Future Vector or Telepathic Network | H31: When you take a Slow turn, your first test that turn gains Advantage. | I31: =AND(IFERROR(INDEX($L$2:$L$22,MATCH("Blue",$K$2:$K$22,0)),0)>=2,OR(COUNTIF($N$2:$N$50,"Future Vector")>0,COUNTIF($N$2:$N$50,"Telepathic Network")>0)) -> FALSE | N31: ='Character Builder'!$H$56 -> 0
A32: leyline | B32: Blue | C32: Foresight | D32: Reactive Analysis | E32: ★ | G32: Calculated Patience | H32: When a creature within Attunement Range fails a test, gain Advantage on your next test against it. | I32: =COUNTIF($N$2:$N$50,"Calculated Patience")>0 -> FALSE | N32: ='Character Builder'!$H$57 -> 0
A33: leyline | B33: Blue | C33: Foresight | D33: Probable Outcome | E33: ∞ | G33: Reactive Analysis | H33: After all creatures choose Fast or Slow turn, you may change your choice. | I33: =COUNTIF($N$2:$N$50,"Reactive Analysis")>0 -> FALSE | N33: ='Character Builder'!$H$58 -> 0
A34: leyline | B34: Blue | C34: Foresight | D34: Foretold Conclusion | E34: ★ | F34: 1 Focus | G34: Probable Outcome; Blue 2+ | H34: When you roll the Plot Die, spend 1 Focus to reroll it and keep either result. | I34: =AND(COUNTIF($N$2:$N$50,"Probable Outcome")>0,IFERROR(INDEX($L$2:$L$22,MATCH("Blue",$K$2:$K$22,0)),0)>=2) -> FALSE | N34: ='Character Builder'!$H$59 -> 0
A35: leyline | B35: Blue | C35: Foresight | D35: Collected | E35: ∞ | G35: Foretold Conclusion; Blue 3+ | H35: Increase your Cognitive and Spiritual Defenses by 2. | I35: =AND(COUNTIF($N$2:$N$50,"Foretold Conclusion")>0,IFERROR(INDEX($L$2:$L$22,MATCH("Blue",$K$2:$K$22,0)),0)>=3) -> FALSE | N35: ='Character Builder'!$H$60 -> 0
A36: leyline | B36: Blue | C36: Calculation | D36: Inertial Sense | E36: ∞ | H36: You ignore Disadvantage on tests caused by movement. After moving 10+ ft, add half [Die] to your next Physical test. | I36: =TRUE -> TRUE | N36: ='Character Builder'!$H$61 -> 0
A37: leyline | B37: Blue | C37: Illusion | D37: Redirect Momentum | E37: ⟲ | F37: 1 Investiture | G37: Subtle Suggestion | H37: When a creature within Attunement Range moves, spend 1 Investiture to test Illusion vs. Physical. On a success, reduce its remaining movement by [Size] or push it [Size] ft in any direction. | I37: =COUNTIF($N$2:$N$50,"Inertial Sense")>0 -> FALSE | N37: ='Character Builder'!$H$62 -> 0
A38: leyline | B38: Blue | C38: Illusion | D38: Velocity Shift | E38: ★ | G38: Redirect Momentum | H38: When an ally within Attunement Range moves, they may move an additional [Size] ft without provoking Reactions. | I38: =COUNTIF($N$2:$N$50,"Inertial Sense")>0 -> FALSE | N38: ='Character Builder'!$H$63 -> 0
A39: leyline | B39: Blue | C39: Illusion | D39: Holographic Illusion | E39: ▶ | F39: Variable Investiture | G39: Phantom Barricade | H39: Spend 1 Investiture to create an illusion within Attunement Range. The illusion cannot exceed [Size]. Illusions cost 1 Investiture every 10 minutes, unless it depicts a character or complex object. Complex illusions cost 1 Investiture every round, and can move up to your movement rate. You can use a Free Action to have your illusion perform simple, mindless tasks, and an Action to have it perform something requiring your attention (such as a conversation). | I39: =OR(COUNTIF($N$2:$N$50,"Redirect Momentum")>0,COUNTIF($N$2:$N$50,"Velocity Shift")>0) -> FALSE | N39: ='Character Builder'!$H$64 -> 0
A40: leyline | B40: Blue | C40: Illusion | D40: Phantom Barricade | E40: ▶ | F40: 1 Investiture | G40: Subtle Suggestion; Blue 2+ | H40: Create a shimmering barrier at a point within Attunement Range. It has HP equal to 2[Die] provides cover, and blocks movement. | I40: =AND(COUNTIF($N$2:$N$50,"Vector Control")>0,IFERROR(INDEX($L$2:$L$22,MATCH("Blue",$K$2:$K$22,0)),0)>=2) -> FALSE | N40: ='Character Builder'!$H$65 -> 0
...
